Workbook

Sheet Current List
A1: CS# | B1: Store # | C1: 5 Digit Store | D1: Div | E1: Reg | F1: Dist | G1: Cluster | H1: Address | I1: City | J1: State | K1: Zip | L1: Store Type | M1: PM/SPM | N1: Layout Validation Status | O1: MV or Store Labor? | P1: Merchandising Hours | Q1: GC | R1: MV | S1: Unit Configuration | T1: MSD | U1: CSD | V1: Notes
A2: 190032 | B2: 10880 | C2: 10880 | D2: 07 | E2: 37 | F2: 03 | G2: 149 | H2: 8580 N. MACARTHUR BLVD | I2: IRVING | J2: TX | K2: 75063 | L2: Freestanding | M2: Soto; Joseph | N2: Approved | O2: MV | P2: 64 | Q2: Core CMCI | R2: Channel Partners | S2: 3 | T2: 46300 | U2: =T2+7
A3: 190020 | B3: 10996 | C3: 10996 | D3: 07 | E3: 33 | F3: 01 | G3: 145 | H3: 9663 W. FM 1097 RD. | I3: WILLIS | J3: TX | K3: 77318 | L3: Freestanding | M3: Cathey; Chris C. | N3: Approved | O3: MV | P3: 32 | Q3: Core CMCI | R3: Pivotal | S3: 3 | T3: 46307 | U3: =T3+7
A4: 189469 | B4: 6893 | C4: 06893 | D4: 07 | E4: 35 | F4: 02 | G4: 147 | H4: 3569 FAR WEST BLVD. | I4: AUSTIN | J4: TX | K4: 78731 | L4: Strip Shopping Center | M4: Soto; Joseph | N4: Approved | O4: N/A | P4: 0 | Q4: Core CMCI | R4: N/A | S4: 3 | T4: 46307 | U4: =T4+7
A5: 190027 | B5: 10691 | C5: 10691 | D5: 07 | E5: 35 | F5: 01 | G5: 147 | H5: 302 GATEWAY NORTH | I5: MARBLE FALLS | J5: TX | K5: 78654 | L5: Freestanding | M5: Soto; Joseph | N5: Approved | O5: MV | P5: 44 | Q5: Core CMCI | R5: Merchco | S5: 3 | T5: 46307 | U5: =T5+7
A6: 190030 | B6: 10633 | C6: 10633 | D6: 07 | E6: 35 | F6: 04 | G6: 148 | H6: 3502 SE MILITARY DR. | I6: SAN ANTONIO | J6: TX | K6: 78223 | L6: Freestanding | M6: Soto; Joseph | N6: Approved | O6: MV | P6: 6 | Q6: Core CMCI | R6: Pivotal | S6: 3 | T6: 46307 | U6: =T6+7
A7: 189985 | B7: 10324 | C7: 10324 | D7: 07 | E7: 36 | F7: 05 | G7: 149 | H7: 6420 GASTON AVE. | I7: DALLAS | J7: TX | K7: 75214 | L7: Convenience | M7: Soto; Joseph | N7: Approved | O7: Store Labor | P7: 22 | Q7: Core CMCI | R7: N/A | S7: 4 | T7: 46307 | U7: =T7+7
A8: 190033 | B8: 10642 | C8: 10642 | D8: 07 | E8: 37 | F8: 05 | G8: 149 | H8: 1101 FM 2181 | I8: CORINTH | J8: TX | K8: 76210 | L8: Freestanding | M8: Soto; Joseph | N8: Approved | O8: MV | P8: 34 | Q8: Core CMCI | R8: Channel Partners | S8: 3 | T8: 46307 | U8: =T8+7
A9: 189518 | B9: 7092 | C9: 07092 | D9: 07 | E9: 33 | F9: 02 | G9: 145 | H9: 110 W. 20TH ST. | I9: HOUSTON | J9: TX | K9: 77008 | L9: Freestanding | M9: Cathey; Chris C. | N9: Approved | O9: MV | P9: 70 | Q9: Core CMCI | R9: Pivotal | S9: 3 | T9: 46314 | U9: =T9+7
A10: 189171 | B10: 1996 | C10: 01996 | D10: 07 | E10: 34 | F10: 01 | G10: 146 | H10: 24950 FRANZ RD. | I10: KATY | J10: TX | K10: 77493 | L10: Freestanding | M10: Soto; Joseph | N10: Approved | O10: Store Labor | P10: 38 | Q10: Core CMCI | R10: N/A | S10: 3 | T10: 46314 | U10: =T10+7
A11: 190024 | B11: 10671 | C11: 10671 | D11: 07 | E11: 34 | F11: 04 | G11: 146 | H11: 10420 FM 1464 | I11: RICHMOND | J11: TX | K11: 77407 | L11: Freestanding | M11: Soto; Joseph | N11: Approved | O11: Store Labor | P11: 8 | Q11: Core CMCI | R11: N/A | S11: 3 | T11: 46314 | U11: =T11+7
A12: 190025 | B12: 10637 | C12: 10637 | D12: 07 | E12: 34 | F12: 04 | G12: 147 | H12: 6750 READING ROAD | I12: ROSENBERG | J12: TX | K12: 77471 | L12: Freestanding | M12: Soto; Joseph | N12: Approved | O12: Store Labor | P12: 14 | Q12: Core CMCI | R12: N/A | S12: 3 | T12: 46314 | U12: =T12+7
A13: 190026 | B13: 10875 | C13: 10875 | D13: 07 | E13: 35 | F13: 01 | G13: 147 | H13: 3000 RM 1431 | I13: ROUND ROCK | J13: TX | K13: 78681 | L13: Freestanding | M13: Soto; Joseph | N13: Approved | O13: Store Labor | P13: 10 | Q13: Core CMCI | R13: N/A | S13: 3 | T13: 46314 | U13: =T13+7
... A15: 190028 | B15: 10947 | C15: 10947 | D15: 07 | E15: 35 | F15: 03 | G15: 148 | H15: 1910 STATE HIGHWAY 46 W | I15: NEW BRAUNFELS | J15: TX | K15: 78132 | L15: Freestanding | M15: Soto; Joseph | N15: Approved | O15: Store Labor | P15: 6 | Q15: Core CMCI | R15: N/A | S15: 3 | T15: 46314 | U15: =T15+7
A16: 189620 | B16: 8345 | C16: 08345 | D16: 07 | E16: 37 | F16: 02 | G16: 149 | H16: 5195 LAKE RIDGE PKWY. | I16: GRAND PRAIRIE | J16: TX | K16: 75052 | L16: Freestanding | M16: Soto; Joseph | N16: Approved | O16: N/A | P16: 0 | Q16: Core CMCI | R16: N/A | S16: 2 - Right Hinge | T16: 46314 | U16: =T16+7
A17: 189473 | B17: 6865 | C17: 06865 | D17: 07 | E17: 37 | F17: 03 | G17: 149 | H17: 1099 W. MAIN ST | I17: LEWISVILLE | J17: TX | K17: 75067 | L17: Freestanding | M17: Soto; Joseph | N17: Approved | O17: MV | P17: 52 | Q17: Core CMCI | R17: Channel Partners | S17: 4 | T17: 46314 | U17: =T17+7
A18: 189419 | B18: 5839 | C18: 05839 | D18: 07 | E18: 33 | F18: 01 | G18: 145 | H18: 8960 BARKER CYPRESS RD. | I18: CYPRESS | J18: TX | K18: 77433 | L18: Freestanding | M18: Cathey; Chris C. | N18: Approved | O18: MV | P18: 10 | Q18: Core CMCI | R18: Pivotal | S18: 3 | T18: 46321 | U18: =T18+7
A19: 189977 | B19: 10594 | C19: 10594 | D19: 07 | E19: 32 | F19: 03 | G19: 145 | H19: 500 N. CARROLLTON AVE. | I19: NEW ORLEANS | J19: LA | K19: 70119 | L19: Freestanding | M19: Cathey; Chris C. | N19: Approved | O19: Store Labor | P19: 34 | Q19: Core CMCI | R19: N/A | S19: 3 | T19: 46321 | U19: =T19+7
A20: 189422 | B20: 5651 | C20: 05651 | D20: 07 | E20: 34 | F20: 02 | G20: 146 | H20: 1602 EAST HIGHWAY 83 | I20: WESLACO | J20: TX | K20: 78596 | L20: Freestanding | M20: Soto; Joseph | N20: Approved | O20: MV | P20: 52 | Q20: Core CMCI | R20: Merchco | S20: 4 | T20: 46321 | U20: =T20+7
A21: 189421 | B21: 5884 | C21: 05884 | D21: 07 | E21: 34 | F21: 01 | G21: 146 | H21: 12260 BELLAIRE BLVD. | I21: HOUSTON | J21: TX | K21: 77072 | L21: Freestanding | M21: Soto; Joseph | N21: Approved | O21: Store Labor | P21: 30 | Q21: Core CMCI | R21: N/A | S21: 3 | T21: 46321 | U21: =T21+7
A22: 189523 | B22: 7805 | C22: 07805 | D22: 07 | E22: 34 | F22: 04 | G22: 147 | H22: 5757 NEW TERRITORY BLVD | I22: SUGAR LAND | J22: TX | K22: 77479 | L22: Freestanding | M22: Soto; Joseph | N22: Approved | O22: N/A | P22: 0 | Q22: Core CMCI | R22: N/A | S22: 3 | T22: 46321 | U22: =T22+7
A23: 189425 | B23: 5776 | C23: 05776 | D23: 07 | E23: 35 | F23: 02 | G23: 147 | H23: 105 WONDERWORLD DRIVE | I23: SAN MARCOS | J23: TX | K23: 78666 | L23: Freestanding Pad | M23: Soto; Joseph | N23: Approved | O23: MV | P23: 74 | Q23: Core CMCI | R23: Merchco | S23: 3 | T23: 46321 | U23: =T23+7
A24: 189074 | B24: 1430 | C24: 01430 | D24: 07 | E24: 35 | F24: 02 | G24: 148 | H24: 2101 S. LAMAR BLVD., UNIT B | I24: AUSTIN | J24: TX | K24: 78704 | L24: Strip Shopping Center | M24: Soto; Joseph | N24: Approved | O24: MV | P24: 40 | Q24: Core CMCI | R24: Pivotal | S24: 3 | T24: 46321 | U24: =T24+7
A25: 189470 | B25: 6822 | C25: 06822 | D25: 07 | E25: 35 | F25: 02 | G25: 148 | H25: 5256 BURNET RD STE B | I25: AUSTIN | J25: TX | K25: 78756 | L25: Freestanding | M25: Soto; Joseph | N25: Approved | O25: Store Labor | P25: 12 | Q25: Core CMCI | R25: N/A | S25: 3 | T25: 46321 | U25: =T25+7
A26: 189281 | B26: 3187 | C26: 03187 | D26: 07 | E26: 37 | F26: 03 | G26: 149 | H26: 1000 E. SANDY LAKE RD. | I26: COPPELL | J26: TX | K26: 75019 | L26: Freestanding Pad | M26: Soto; Joseph | N26: Approved | O26: MV | P26: 46 | Q26: Core CMCI | R26: Channel Partners | S26: 3 | T26: 46321 | U26: =T26+7
A27: 189528 | B27: 7787 | C27: 07787 | D27: 07 | E27: 37 | F27: 03 | G27: 149 | H27: 2220 CROSS TIMBERS RD | I27: FLOWER MOUND | J27: TX | K27: 75028 | L27: Freestanding | M27: Soto; Joseph | N27: Approved | O27: N/A | P27: 0 | Q27: Core CMCI | R27: N/A | S27: 3 | T27: 46321 | U27: =T27+7
A28: 189516 | B28: 7448 | C28: 07448 | D28: 07 | E28: 33 | F28: 01 | G28: 145 | H28: 815 W. MAIN ST. | I28: TOMBALL | J28: TX | K28: 77375 | L28: Freestanding | M28: Cathey; Chris C. | N28: Approved | O28: MV | P28: 36 | Q28: Core CMCI | R28: Pivotal | S28: 3 | T28: 46328 | U28: =T28+7
A29: 190021 | B29: 10664 | C29: 10664 | D29: 07 | E29: 33 | F29: 01 | G29: 145 | H29: 2180 WOODFOREST PARKWAY N. | I29: MONTGOMERY | J29: TX | K29: 77316 | L29: Freestanding Pad | M29: Cathey; Chris C. | N29: Approved | O29: Store Labor | P29: 34 | Q29: Core CMCI | R29: N/A | S29: 3 | T29: 46328 | U29: =T29+7
A30: 189926 | B30: 10107 | C30: 10107 | D30: 07 | E30: 34 | F30: 02 | G30: 146 | H30: 2300 N CONWAY AVE. | I30: MISSION | J30: TX | K30: 78574 | L30: Freestanding | M30: Soto; Joseph | N30: Not Validated Yet | Q30: Core CMCI | R30: Merchco | T30: 46328 | U30: =T30+7
A31: 189978 | B31: 10405 | C31: 10405 | D31: 07 | E31: 34 | F31: 02 | G31: 146 | H31: 103 W. MONTE CRISTO RD. | I31: EDINBURG | J31: TX | K31: 78541 | L31: Freestanding | M31: Soto; Joseph | N31: Approved | O31: MV | P31: 62 | Q31: Core CMCI | R31: Merchco | S31: 4 | T31: 46328 | U31: =T31+7
A32: 189279 | B32: 3693 | C32: 03693 | D32: 07 | E32: 34 | F32: 04 | G32: 147 | H32: 7950 S. GESSNER RD. | I32: HOUSTON | J32: TX | K32: 77036 | L32: Freestanding | M32: Soto; Joseph | N32: Approved | O32: MV | P32: 56 | Q32: Core CMCI | R32: Merchco | S32: 3 | T32: 46328 | U32: =T32+7
A33: 189322 | B33: 4474 | C33: 04474 | D33: 07 | E33: 34 | F33: 04 | G33: 147 | H33: 2781 DULLES AVE. | I33: MISSOURI CITY | J33: TX | K33: 77459 | L33: Freestanding | M33: Soto; Joseph | N33: Approved | O33: MV | P33: 66 | Q33: Core CMCI | R33: Merchco | S33: 3 | T33: 46328 | U33: =T33+7
A34: 189984 | B34: 10595 | C34: 10595 | D34: 07 | E34: 35 | F34: 03 | G34: 148 | H34: 200 CIBOLO VALLEY DR. | I34: CIBOLO | J34: TX | K34: 78108 | L34: Freestanding | M34: Soto; Joseph | N34: Approved | O34: Store Labor | P34: 36 | Q34: Core CMCI | R34: N/A | S34: 4 | T34: 46328 | U34: =T34+7
A35: 189526 | B35: 7307 | C35: 07307 | D35: 07 | E35: 35 | F35: 04 | G35: 148 | H35: 2018 CULEBRA RD. | I35: SAN ANTONIO | J35: TX | K35: 78201 | L35: Freestanding | M35: Soto; Joseph | N35: Not Validated Yet | Q35: Core CMCI | R35: Pivotal | T35: 46328 | U35: =T35+7
A36: 189474 | B36: 6960 | C36: 06960 | D36: 07 | E36: 37 | F36: 04 | G36: 149 | H36: 2142 N JOSEY LN | I36: CARROLLTON | J36: TX | K36: 75006 | L36: Freestanding | M36: Soto; Joseph | N36: Approved | O36: N/A | P36: 0 | Q36: Core CMCI | R36: N/A | S36: 3 | T36: 46328 | U36: =T36+7
A37: 189529 | B37: 7804 | C37: 07804 | D37: 07 | E37: 37 | F37: 04 | G37: 149 | H37: 6401 W PARKER RD | I37: PLANO | J37: TX | K37: 75093 | L37: Freestanding | M37: Soto; Joseph | N37: Approved | O37: N/A | P37: 0 | Q37: Core CMCI | R37: N/A | S37: 3 | T37: 46328 | U37: =T37+7
A38: 189519 | B38: 7476 | C38: 07476 | D38: 07 | E38: 33 | F38: 02 | G38: 145 | H38: 5401 WASHINGTON AVE | I38: HOUSTON | J38: TX | K38: 77007 | L38: Freestanding | M38: Cathey; Chris C. | N38: Not Validated Yet | Q38: Core CMCI | R38: Pivotal | T38: 46335 | U38: =T38+7
A39: 188919 | B39: 248 | C39: 00248 | D39: 07 | E39: 34 | F39: 02 | G39: 146 | H39: 2121 W. TRENTON RD. | I39: EDINBURG | J39: TX | K39: 78539 | L39: Freestanding | M39: Soto; Joseph | N39: Not Validated Yet | Q39: Core CMCI | R39: Merchco | T39: 46335 | U39: =T39+7
A40: 189979 | B40: 10350 | C40: 10350 | D40: 07 | E40: 34 | F40: 03 | G40: 146 | H40: 4523 L J PARKWAY | I40: SUGAR LAND | J40: TX | K40: 77479 | L40: Freestanding | M40: Soto; Joseph | N40: Not Validated Yet | Q40: Core CMCI | R40: Merchco | T40: 46335 | U40: =T40+7
A41: 189927 | B41: 10177 | C41: 10177 | D41: 07 | E41: 34 | F41: 04 | G41: 147 | H41: 2720 FM 1463 | I41: KATY | J41: TX | K41: 77494 | L41: Freestanding | M41: Soto; Joseph | N41: Not Validated Yet | Q41: Core CMCI | R41: Merchco | T41: 46335 | U41: =T41+7
...

Sheet Rejected Candidates
A1: Store # | B1: 5 Digit Store | C1: CS# | D1: Div | E1: Reg | F1: Dist | G1: Cluster | H1: Address | I1: City | J1: State | K1: Zip | L1: Store Type | M1: PM/SPM | N1: Layout Validation Status | O1: MV or Store Labor? | P1: Merchandising Hours | Q1: Unit Configuration | R1: MSD | S1: CSD
A2: 9481 | B2: 09481 | C2: 189774 | D2: 09 | E2: 89 | F2: 02 | G2: 169 | H2: 12444 BEACH BOULEVARD | I2: STANTON | J2: CA | K2: 90680 | L2: Freestanding | M2: Winkler; Jacob S | N2: Rejected | R2: 46335 | S2: =R2+7
A3: 915 | B3: 00915 | C3: 188989 | D3: 01 | E3: 02 | F3: 03 | G3: 105 | H3: 19 DODGE ST. | I3: BEVERLY | J3: MA | K3: 01915 | L3: Freestanding Pad | M3: Wheeler; Nicolas | N3: Rejected | R3: 46300 | S3: =R3+7
A4: 224 | B4: 00224 | C4: 188874 | D4: 01 | E4: 02 | F4: 03 | G4: 105 | H4: 650 MAIN STREET | I4: READING | J4: MA | K4: 01867 | L4: Downtown | M4: Wheeler; Nicolas | N4: Rejected | R4: 46314 | S4: =R4+7
A5: 860 | B5: 00860 | C5: 188992 | D5: 01 | E5: 03 | F5: 02 | G5: 106 | H5: 6 POST OFFICE SQ | I5: HARWICHPORT | J5: MA | K5: 02646 | L5: Convenience | M5: Wheeler; Nicolas | N5: Rejected | R5: 46356 | S5: =R5+7
A6: 1213 | B6: 01213 | C6: 189038 | D6: 01 | E6: 04 | F6: 03 | G6: 109 | H6: 94 PARK STREET | I6: NEW CANAAN | J6: CT | K6: 06840 | L6: Downtown | M6: Charlotinambrose; Mildred | N6: Rejected | R6: 46335 | S6: =R6+7
A7: 11060 | B7: 11060 | C7: 190007 | D7: 02 | E7: 06 | F7: 05 | G7: 115 | H7: 1-50 50TH AVE | I7: LONG ISLAND CITY | J7: NY | K7: 11101 | L7: Downtown | M7: Kaegi; Jacqueline | N7: Rejected | R7: 46356 | S7: =R7+7
A8: 1833 | B8: 01833 | C8: 189103 | D8: 02 | E8: 17 | F8: 02 | G8: 120 | H8: 4238 WILSON BLVD/BALLSTON COMMONS #1831 | I8: ARLINGTON | J8: VA | K8: 22203 | L8: Regional Mall | M8: Meath; Lori A. | N8: Rejected | R8: 46314 | S8: =R8+7
A9: 8088 | B9: 08088 | C9: 189571 | D9: 03 | E9: 58 | F9: 02 | G9: 130 | H9: 2100 W. STADIUM BLVD. | I9: ANN ARBOR | J9: MI | K9: 48103 | L9: Freestanding | M9: Clark; Josh D. | N9: Rejected | R9: 46328 | S9: =R9+7
A10: 1389 | B10: 01389 | C10: 189072 | D10: 04 | E10: 19 | F10: 02 | G10: 140 | H10: 2912 CHAIN BRIDGE ROAD | I10: OAKTON | J10: VA | K10: 22124 | L10: Strip Shopping Center | M10: Meath; Lori A. | N10: Rejected | R10: 46307 | S10: =R10+7
A11: 3705 | B11: 03705 | C11: 189277 | D11: 05 | E11: 83 | F11: 03 | G11: 144 | H11: 10701 NW 41ST ST | I11: DORAL | J11: FL | K11: 33178 | L11: Freestanding | M11: townsend; kevin | N11: Rejected | R11: 46356 | S11: =R11+7
A12: 5443 | B12: 05443 | C12: 189374 | D12: 07 | E12: 32 | F12: 02 | G12: 145 | H12: 1920 KALISTE SALOOM | I12: LAFAYETTE | J12: LA | K12: 70508 | L12: Freestanding | M12: Cathey; Chris C. | N12: Rejected | R12: 46314 | S12: =R12+7
A13: 7435 | B13: 07435 | C13: 189520 | D13: 07 | E13: 33 | F13: 03 | G13: 145 | H13: 23865 FM 1314 RD. | I13: PORTER | J13: TX | K13: 77365 | L13: Freestanding | M13: Cathey; Chris C. | N13: Rejected | R13: 46335 | S13: =R13+7
... A30: 8895 | B30: 08895 | C30: 189691 | D30: 09 | E30: 88 | F30: 02 | G30: 170 | H30: 775 E. FOOTHILL BOULEVARD | I30: POMONA | J30: CA | K30: 91767 | L30: Strip Shopping Center | M30: Winkler; Jacob S | N30: Rejected | R30: 46342 | S30: =R30+7
A31: 189064 | B31: 1315 | C31: 01315 | D31: 04 | E31: 14 | F31: 04 | G31: 138 | H31: 1101 SOUTHWEST END BLVD. | I31: QUAKERTOWN | J31: PA | K31: 18951 | L31: Freestanding | M31: Santalucia; Dawn | N31: Rejected | R31: 46321 | S31: =R31+7
A32: 189566 | B32: 8016 | C32: 08016 | D32: 03 | E32: 57 | F32: 05 | G32: 129 | H32: 40925 GARFIELD ROAD | I32: CLINTON TOWNSHIP | J32: MI | K32: 48038 | L32: Freestanding | M32: Clark; Josh D. | N32: Rejected | R32: 46328 | S32: =R32+7
A33: 189572 | B33: 8089 | C33: 08089 | D33: 03 | E33: 58 | F33: 02 | G33: 130 | H33: 935 S. MAIN ST. | I33: CHELSEA | J33: MI | K33: 48118 | L33: Freestanding | M33: Clark; Josh D. | N33: Rejected | R33: 46328 | S33: =R33+7
A34: 189073 | B34: 1411 | C34: 01411 | D34: 04 | E34: 19 | F34: 02 | G34: 140 | H34: 8124 ARLINGTON BLVD, YORKTOWN CTR | I34: FALLS CHURCH | J34: VA | K34: 22042 | L34: Strip Shopping Center | M34: Meath; Lori A. | N34: Rejected | R34: 46328 | S34: =R34+7
A35: 189198 | B35: 3154 | C35: 03154 | D35: 01 | E35: 05 | F35: 01 | G35: 110 | H35: 59 MAIN STREET | I35: WARWICK | J35: NY | K35: 10990 | L35: Freestanding | M35: Messer; Laura R | N35: Rejected | R35: 46335 | S35: =R35+7
A36: 189041 | B36: 1414 | C36: 01414 | D36: 01 | E36: 07 | F36: 01 | G36: 112 | H36: 1195 OAKLAWN AVENUE | I36: CRANSTON | J36: RI | K36: 02920 | L36: Freestanding Pad | M36: Messer; Laura R | N36: Rejected | R36: 46335 | S36: =R36+7
A37: 189573 | B37: 8216 | C37: 08216 | D37: 03 | E37: 58 | F37: 02 | G37: 130 | H37: 1700 SOUTH INDUSTRIAL HIGHWAY | I37: ANN ARBOR | J37: MI | K37: 48104 | L37: Freestanding | M37: Clark; Josh D. | N37: Rejected | R37: 46335 | S37: =R37+7
A38: 189268 | B38: 3218 | C38: 03218 | D38: 05 | E38: 41 | F38: 01 | G38: 142 | H38: 10200 SEMINOLE BLVD | I38: SEMINOLE | J38: FL | K38: 33778 | L38: Freestanding | M38: townsend; kevin | N38: Rejected | R38: 46335 | S38: =R38+7
A39: 189625 | B39: 8420 | C39: 08420 | D39: 08 | E39: 30 | F39: 04 | G39: 151 | H39: 7740 N CORTARO RD | I39: TUCSON | J39: AZ | K39: 85743 | L39: Freestanding | M39: Sotelo; Rolly | N39: Rejected | R39: 46335 | S39: =R39+7
A40: 189406 | B40: 5741 | C40: 05741 | D40: 03 | E40: 58 | F40: 01 | G40: 129 | H40: 7488 VILLAGE CENTER DR. | I40: WHITMORE LAKE | J40: MI | K40: 48189 | L40: Freestanding Pad | M40: Clark; Josh D. | N40: Rejected | R40: 46356 | S40: =R40+7
A41: 188962 | B41: 660 | C41: 00660 | D41: 04 | E41: 13 | F41: 01 | G41: 135 | H41: 9875 BUSTLETON AVENUE | I41: PHILADELPHIA | J41: PA | K41: 19115 | L41: Freestanding Pad | M41: Santalucia; Dawn | N41: Rejected | R41: 46321 | S41: =R41+7
A42: 189840 | B42: 9784 | C42: 09784 | D42: 09 | E42: 90 | F42: 02 | G42: 172 | H42: 1030 COLORADO BLVD. | I42: EAGLE ROCK | J42: CA | K42: 90041 | L42: Freestanding | M42: Cathey; Chris C. | N42: Approved | O42: MV | P42: 60 | Q42: 2 | R42: 46314 | S42: =R42+7

Sheet Assumptions
A1: Logistics Plan - Assumptions (edit yellow cells; plan recalculates)
A3: Global inputs
A4: Default units per store when config is blank/TBD | B4: 3 | C4: Most common configuration among the 35 validated stores (29 are 3-unit)
A5: Delivery buffer before MSD (business days) | B5: 3 | C5: Units on site, checked and staged before install starts. ASSUMPTION - confirm with vendor/CVS
A6: Install days per store (crew-days) | B6: 1 | C6: ASSUMPTION - confirm actual install duration per unit config
A9: Transit time from vendor/staging point to region (business days)
A10: Region | B10: Transit days | C10: Note
A11: DFW | B11: 2 | C11: PLACEHOLDER - update once ship-from point is known
A12: Houston | B12: 2 | C12: PLACEHOLDER
A13: Austin / Central | B13: 2 | C13: PLACEHOLDER
A14: San Antonio | B14: 2 | C14: PLACEHOLDER
A15: South TX | B15: 3 | C15: PLACEHOLDER - RGV / Corpus are long hauls
A16: Outlier | B16: 4 | C16: PLACEHOLDER - Amarillo and New Orleans are out of the way
A18: Definitions used
A19: MSD = date install window opens per the store list. CSD = MSD + 7 days (existing formula in the list).
A20: Deliver-by = MSD less the delivery buffer (business days). Ship-by = Deliver-by less regional transit days.
A21: Units come from the Unit Configuration column; stores not yet validated have none, so the default above is used and flagged TBD.
A22: Regions are grouped by metro so one crew/truck run covers a cluster. Killeen is grouped with Austin / Central.
A23: Plan tab pulls MSD, labor and status live from Current List by CS#.

Sheet Logistics Plan
A1: Core CMCI - Consultation Room Logistics Plan
A2: Sorted by region, then MSD. Dates and units are formulas driven by the Assumptions tab and Current List.
A4: Region | B4: CS# | C4: Store # | D4: City | E4: State | F4: Zip | G4: Store Type | H4: Labor (MV / Store) | I4: MV Vendor | J4: Layout Status | K4: Config (raw) | L4: Units | M4: Config | N4: MSD | O4: Deliver-by | P4: Ship-by | Q4: Ship week of (Mon) | R4: CSD | S4: Flags
A5: DFW | B5: 190032 | C5: 10880 | D5: Irving | E5: TX | F5: 75063 | G5: =INDEX('Current List'!$L:$L,MATCH($B5,'Current List'!$A:$A,0)) | H5: =IF(INDEX('Current List'!$O:$O,MATCH($B5,'Current List'!$A:$A,0))=0,"TBD",INDEX('Current List'!$O:$O,MATCH($B5,'Current List'!$A:$A,0))) | I5: =IF(OR(INDEX('Current List'!$R:$R,MATCH($B5,'Current List'!$A:$A,0))=0,INDEX('Current List'!$R:$R,MATCH($B5,'Current List'!$A:$A,0))="N/A"),"-",INDEX('Current List'!$R:$R,MATCH($B5,'Current List'!$A:$A,0))) | J5: =INDEX('Current List'!$N:$N,MATCH($B5,'Current List'!$A:$A,0)) | K5: =IF(INDEX('Current List'!$S:$S,MATCH($B5,'Current List'!$A:$A,0))=0,"",INDEX('Current List'!$S:$S,MATCH($B5,'Current List'!$A:$A,0))) | L5: =IFERROR(IF(ISNUMBER(K5),K5,VALUE(LEFT(K5,1))),Assumptions!$B$4) | M5: =IF(K5="","TBD","Confirmed") | N5: =INDEX('Current List'!$T:$T,MATCH($B5,'Current List'!$A:$A,0)) | O5: =WORKDAY(N5,-Assumptions!$B$5) | P5: =WORKDAY(O5,-VLOOKUP(A5,Assumptions!$A$11:$B$16,2,FALSE)) | Q5: =P5-WEEKDAY(P5,3) | R5: =INDEX('Current List'!$U:$U,MATCH($B5,'Current List'!$A:$A,0)) | S5: =TRIM(IF(J5<>"Approved","Layout not validated; ","")&IF(M5="TBD","Config TBD (default units); ","")&IF(H5="TBD","Labor TBD; ","")&IF(A5="Outlier","Remote / out of route; ","")&IF(A5="South TX","Long haul; ",""))
A6: DFW | B6: 190033 | C6: 10642 | D6: Corinth | E6: TX | F6: 76210 | G6: =INDEX('Current List'!$L:$L,MATCH($B6,'Current List'!$A:$A,0)) | H6: =IF(INDEX('Current List'!$O:$O,MATCH($B6,'Current List'!$A:$A,0))=0,"TBD",INDEX('Current List'!$O:$O,MATCH($B6,'Current List'!$A:$A,0))) | I6: =IF(OR(INDEX('Current List'!$R:$R,MATCH($B6,'Current List'!$A:$A,0))=0,INDEX('Current List'!$R:$R,MATCH($B6,'Current List'!$A:$A,0))="N/A"),"-",INDEX('Current List'!$R:$R,MATCH($B6,'Current List'!$A:$A,0))) | J6: =INDEX('Current List'!$N:$N,MATCH($B6,'Current List'!$A:$A,0)) | K6: =IF(INDEX('Current List'!$S:$S,MATCH($B6,'Current List'!$A:$A,0))=0,"",INDEX('Current List'!$S:$S,MATCH($B6,'Current List'!$A:$A,0))) | L6: =IFERROR(IF(ISNUMBER(K6),K6,VALUE(LEFT(K6,1))),Assumptions!$B$4) | M6: =IF(K6="","TBD","Confirmed") | N6: =INDEX('Current List'!$T:$T,MATCH($B6,'Current List'!$A:$A,0)) | O6: =WORKDAY(N6,-Assumptions!$B$5) | P6: =WORKDAY(O6,-VLOOKUP(A6,Assumptions!$A$11:$B$16,2,FALSE)) | Q6: =P6-WEEKDAY(P6,3) | R6: =INDEX('Current List'!$U:$U,MATCH($B6,'Current List'!$A:$A,0)) | S6: =TRIM(IF(J6<>"Approved","Layout not validated; ","")&IF(M6="TBD","Config TBD (default units); ","")&IF(H6="TBD","Labor TBD; ","")&IF(A6="Outlier","Remote / out of route; ","")&IF(A6="South TX","Long haul; ",""))
A7: DFW | B7: 189985 | C7: 10324 | D7: Dallas | E7: TX | F7: 75214 | G7: =INDEX('Current List'!$L:$L,MATCH($B7,'Current List'!$A:$A,0)) | H7: =IF(INDEX('Current List'!$O:$O,MATCH($B7,'Current List'!$A:$A,0))=0,"TBD",INDEX('Current List'!$O:$O,MATCH($B7,'Current List'!$A:$A,0))) | I7: =IF(OR(INDEX('Current List'!$R:$R,MATCH($B7,'Current List'!$A:$A,0))=0,INDEX('Current List'!$R:$R,MATCH($B7,'Current List'!$A:$A,0))="N/A"),"-",INDEX('Current List'!$R:$R,MATCH($B7,'Current List'!$A:$A,0))) | J7: =INDEX('Current List'!$N:$N,MATCH($B7,'Current List'!$A:$A,0)) | K7: =IF(INDEX('Current List'!$S:$S,MATCH($B7,'Current List'!$A:$A,0))=0,"",INDEX('Current List'!$S:$S,MATCH($B7,'Current List'!$A:$A,0))) | L7: =IFERROR(IF(ISNUMBER(K7),K7,VALUE(LEFT(K7,1))),Assumptions!$B$4) | M7: =IF(K7="","TBD","Confirmed") | N7: =INDEX('Current List'!$T:$T,MATCH($B7,'Current List'!$A:$A,0)) | O7: =WORKDAY(N7,-Assumptions!$B$5) | P7: =WORKDAY(O7,-VLOOKUP(A7,Assumptions!$A$11:$B$16,2,FALSE)) | Q7: =P7-WEEKDAY(P7,3) | R7: =INDEX('Current List'!$U:$U,MATCH($B7,'Current List'!$A:$A,0)) | S7: =TRIM(IF(J7<>"Approved","Layout not validated; ","")&IF(M7="TBD","Config TBD (default units); ","")&IF(H7="TBD","Labor TBD; ","")&IF(A7="Outlier","Remote / out of route; ","")&IF(A7="South TX","Long haul; ",""))
A8: DFW | B8: 189620 | C8: 8345 | D8: Grand Prairie | E8: TX | F8: 75052 | G8: =INDEX('Current List'!$L:$L,MATCH($B8,'Current List'!$A:$A,0)) | H8: =IF(INDEX('Current List'!$O:$O,MATCH($B8,'Current List'!$A:$A,0))=0,"TBD",INDEX('Current List'!$O:$O,MATCH($B8,'Current List'!$A:$A,0))) | I8: =IF(OR(INDEX('Current List'!$R:$R,MATCH($B8,'Current List'!$A:$A,0))=0,INDEX('Current List'!$R:$R,MATCH($B8,'Current List'!$A:$A,0))="N/A"),"-",INDEX('Current List'!$R:$R,MATCH($B8,'Current List'!$A:$A,0))) | J8: =INDEX('Current List'!$N:$N,MATCH($B8,'Current List'!$A:$A,0)) | K8: =IF(INDEX('Current List'!$S:$S,MATCH($B8,'Current List'!$A:$A,0))=0,"",INDEX('Current List'!$S:$S,MATCH($B8,'Current List'!$A:$A,0))) | L8: =IFERROR(IF(ISNUMBER(K8),K8,VALUE(LEFT(K8,1))),Assumptions!$B$4) | M8: =IF(K8="","TBD","Confirmed") | N8: =INDEX('Current List'!$T:$T,MATCH($B8,'Current List'!$A:$A,0)) | O8: =WORKDAY(N8,-Assumptions!$B$5) | P8: =WORKDAY(O8,-VLOOKUP(A8,Assumptions!$A$11:$B$16,2,FALSE)) | Q8: =P8-WEEKDAY(P8,3) | R8: =INDEX('Current List'!$U:$U,MATCH($B8,'Current List'!$A:$A,0)) | S8: =TRIM(IF(J8<>"Approved","Layout not validated; ","")&IF(M8="TBD","Config TBD (default units); ","")&IF(H8="TBD","Labor TBD; ","")&IF(A8="Outlier","Remote / out of route; ","")&IF(A8="South TX","Long haul; ",""))
A9: DFW | B9: 189473 | C9: 6865 | D9: Lewisville | E9: TX | F9: 75067 | G9: =INDEX('Current List'!$L:$L,MATCH($B9,'Current List'!$A:$A,0)) | H9: =IF(INDEX('Current List'!$O:$O,MATCH($B9,'Current List'!$A:$A,0))=0,"TBD",INDEX('Current List'!$O:$O,MATCH($B9,'Current List'!$A:$A,0))) | I9: =IF(OR(INDEX('Current List'!$R:$R,MATCH($B9,'Current List'!$A:$A,0))=0,INDEX('Current List'!$R:$R,MATCH($B9,'Current List'!$A:$A,0))="N/A"),"-",INDEX('Current List'!$R:$R,MATCH($B9,'Current List'!$A:$A,0))) | J9: =INDEX('Current List'!$N:$N,MATCH($B9,'Current List'!$A:$A,0)) | K9: =IF(INDEX('Current List'!$S:$S,MATCH($B9,'Current List'!$A:$A,0))=0,"",INDEX('Current List'!$S:$S,MATCH($B9,'Current List'!$A:$A,0))) | L9: =IFERROR(IF(ISNUMBER(K9),K9,VALUE(LEFT(K9,1))),Assumptions!$B$4) | M9: =IF(K9="","TBD","Confirmed") | N9: =INDEX('Current List'!$T:$T,MATCH($B9,'Current List'!$A:$A,0)) | O9: =WORKDAY(N9,-Assumptions!$B$5) | P9: =WORKDAY(O9,-VLOOKUP(A9,Assumptions!$A$11:$B$16,2,FALSE)) | Q9: =P9-WEEKDAY(P9,3) | R9: =INDEX('Current List'!$U:$U,MATCH($B9,'Current List'!$A:$A,0)) | S9: =TRIM(IF(J9<>"Approved","Layout not validated; ","")&IF(M9="TBD","Config TBD (default units); ","")&IF(H9="TBD","Labor TBD; ","")&IF(A9="Outlier","Remote / out of route; ","")&IF(A9="South TX","Long haul; ",""))
A10: DFW | B10: 189281 | C10: 3187 | D10: Coppell | E10: TX | F10: 75019 | G10: =INDEX('Current List'!$L:$L,MATCH($B10,'Current List'!$A:$A,0)) | H10: =IF(INDEX('Current List'!$O:$O,MATCH($B10,'Current List'!$A:$A,0))=0,"TBD",INDEX('Current List'!$O:$O,MATCH($B10,'Current List'!$A:$A,0))) | I10: =IF(OR(INDEX('Current List'!$R:$R,MATCH($B10,'Current List'!$A:$A,0))=0,INDEX('Current List'!$R:$R,MATCH($B10,'Current List'!$A:$A,0))="N/A"),"-",INDEX('Current List'!$R:$R,MATCH($B10,'Current List'!$A:$A,0))) | J10: =INDEX('Current List'!$N:$N,MATCH($B10,'Current List'!$A:$A,0)) | K10: =IF(INDEX('Current List'!$S:$S,MATCH($B10,'Current List'!$A:$A,0))=0,"",INDEX('Current List'!$S:$S,MATCH($B10,'Current List'!$A:$A,0))) | L10: =IFERROR(IF(ISNUMBER(K10),K10,VALUE(LEFT(K10,1))),Assumptions!$B$4) | M10: =IF(K10="","TBD","Confirmed") | N10: =INDEX('Current List'!$T:$T,MATCH($B10,'Current List'!$A:$A,0)) | O10: =WORKDAY(N10,-Assumptions!$B$5) | P10: =WORKDAY(O10,-VLOOKUP(A10,Assumptions!$A$11:$B$16,2,FALSE)) | Q10: =P10-WEEKDAY(P10,3) | R10: =INDEX('Current List'!$U:$U,MATCH($B10,'Current List'!$A:$A,0)) | S10: =TRIM(IF(J10<>"Approved","Layout not validated; ","")&IF(M10="TBD","Config TBD (default units); ","")&IF(H10="TBD","Labor TBD; ","")&IF(A10="Outlier","Remote / out of route; ","")&IF(A10="South TX","Long haul; ",""))
A11: DFW | B11: 189528 | C11: 7787 | D11: Flower Mound | E11: TX | F11: 75028 | G11: =INDEX('Current List'!$L:$L,MATCH($B11,'Current List'!$A:$A,0)) | H11: =IF(INDEX('Current List'!$O:$O,MATCH($B11,'Current List'!$A:$A,0))=0,"TBD",INDEX('Current List'!$O:$O,MATCH($B11,'Current List'!$A:$A,0))) | I11: =IF(OR(INDEX('Current List'!$R:$R,MATCH($B11,'Current List'!$A:$A,0))=0,INDEX('Current List'!$R:$R,MATCH($B11,'Current List'!$A:$A,0))="N/A"),"-",INDEX('Current List'!$R:$R,MATCH($B11,'Current List'!$A:$A,0))) | J11: =INDEX('Current List'!$N:$N,MATCH($B11,'Current List'!$A:$A,0)) | K11: =IF(INDEX('Current List'!$S:$S,MATCH($B11,'Current List'!$A:$A,0))=0,"",INDEX('Current List'!$S:$S,MATCH($B11,'Current List'!$A:$A,0))) | L11: =IFERROR(IF(ISNUMBER(K11),K11,VALUE(LEFT(K11,1))),Assumptions!$B$4) | M11: =IF(K11="","TBD","Confirmed") | N11: =INDEX('Current List'!$T:$T,MATCH($B11,'Current List'!$A:$A,0)) | O11: =WORKDAY(N11,-Assumptions!$B$5) | P11: =WORKDAY(O11,-VLOOKUP(A11,Assumptions!$A$11:$B$16,2,FALSE)) | Q11: =P11-WEEKDAY(P11,3) | R11: =INDEX('Current List'!$U:$U,MATCH($B11,'Current List'!$A:$A,0)) | S11: =TRIM(IF(J11<>"Approved","Layout not validated; ","")&IF(M11="TBD","Config TBD (default units); ","")&IF(H11="TBD","Labor TBD; ","")&IF(A11="Outlier","Remote / out of route; ","")&IF(A11="South TX","Long haul; ",""))
A12: DFW | B12: 189474 | C12: 6960 | D12: Carrollton | E12: TX | F12: 75006 | G12: =INDEX('Current List'!$L:$L,MATCH($B12,'Current List'!$A:$A,0)) | H12: =IF(INDEX('Current List'!$O:$O,MATCH($B12,'Current List'!$A:$A,0))=0,"TBD",INDEX('Current List'!$O:$O,MATCH($B12,'Current List'!$A:$A,0))) | I12: =IF(OR(INDEX('Current List'!$R:$R,MATCH($B12,'Current List'!$A:$A,0))=0,INDEX('Current List'!$R:$R,MATCH($B12,'Current List'!$A:$A,0))="N/A"),"-",INDEX('Current List'!$R:$R,MATCH($B12,'Current List'!$A:$A,0))) | J12: =INDEX('Current List'!$N:$N,MATCH($B12,'Current List'!$A:$A,0)) | K12: =IF(INDEX('Current List'!$S:$S,MATCH($B12,'Current List'!$A:$A,0))=0,"",INDEX('Current List'!$S:$S,MATCH($B12,'Current List'!$A:$A,0))) | L12: =IFERROR(IF(ISNUMBER(K12),K12,VALUE(LEFT(K12,1))),Assumptions!$B$4) | M12: =IF(K12="","TBD","Confirmed") | N12: =INDEX('Current List'!$T:$T,MATCH($B12,'Current List'!$A:$A,0)) | O12: =WORKDAY(N12,-Assumptions!$B$5) | P12: =WORKDAY(O12,-VLOOKUP(A12,Assumptions!$A$11:$B$16,2,FALSE)) | Q12: =P12-WEEKDAY(P12,3) | R12: =INDEX('Current List'!$U:$U,MATCH($B12,'Current List'!$A:$A,0)) | S12: =TRIM(IF(J12<>"Approved","Layout not validated; ","")&IF(M12="TBD","Config TBD (default units); ","")&IF(H12="TBD","Labor TBD; ","")&IF(A12="Outlier","Remote / out of route; ","")&IF(A12="South TX","Long haul; ",""))
A13: DFW | B13: 189529 | C13: 7804 | D13: Plano | E13: TX | F13: 75093 | G13: =INDEX('Current List'!$L:$L,MATCH($B13,'Current List'!$A:$A,0)) | H13: =IF(INDEX('Current List'!$O:$O,MATCH($B13,'Current List'!$A:$A,0))=0,"TBD",INDEX('Current List'!$O:$O,MATCH($B13,'Current List'!$A:$A,0))) | I13: =IF(OR(INDEX('Current List'!$R:$R,MATCH($B13,'Current List'!$A:$A,0))=0,INDEX('Current List'!$R:$R,MATCH($B13,'Current List'!$A:$A,0))="N/A"),"-",INDEX('Current List'!$R:$R,MATCH($B13,'Current List'!$A:$A,0))) | J13: =INDEX('Current List'!$N:$N,MATCH($B13,'Current List'!$A:$A,0)) | K13: =IF(INDEX('Current List'!$S:$S,MATCH($B13,'Current List'!$A:$A,0))=0,"",INDEX('Current List'!$S:$S,MATCH($B13,'Current List'!$A:$A,0))) | L13: =IFERROR(IF(ISNUMBER(K13),K13,VALUE(LEFT(K13,1))),Assumptions!$B$4) | M13: =IF(K13="","TBD","Confirmed") | N13: =INDEX('Current List'!$T:$T,MATCH($B13,'Current List'!$A:$A,0)) | O13: =WORKDAY(N13,-Assumptions!$B$5) | P13: =WORKDAY(O13,-VLOOKUP(A13,Assumptions!$A$11:$B$16,2,FALSE)) | Q13: =P13-WEEKDAY(P13,3) | R13: =INDEX('Current List'!$U:$U,MATCH($B13,'Current List'!$A:$A,0)) | S13: =TRIM(IF(J13<>"Approved","Layout not validated; ","")&IF(M13="TBD","Config TBD (default units); ","")&IF(H13="TBD","Labor TBD; ","")&IF(A13="Outlier","Remote / out of route; ","")&IF(A13="South TX","Long haul; ",""))
A14: DFW | B14: 189986 | C14: 10271 | D14: Denton | E14: TX | F14: 76201 | G14: =INDEX('Current List'!$L:$L,MATCH($B14,'Current List'!$A:$A,0)) | H14: =IF(INDEX('Current List'!$O:$O,MATCH($B14,'Current List'!$A:$A,0))=0,"TBD",INDEX('Current List'!$O:$O,MATCH($B14,'Current List'!$A:$A,0))) | I14: =IF(OR(INDEX('Current List'!$R:$R,MATCH($B14,'Current List'!$A:$A,0))=0,INDEX('Current List'!$R:$R,MATCH($B14,'Current List'!$A:$A,0))="N/A"),"-",INDEX('Current List'!$R:$R,MATCH($B14,'Current List'!$A:$A,0))) | J14: =INDEX('Current List'!$N:$N,MATCH($B14,'Current List'!$A:$A,0)) | K14: =IF(INDEX('Current List'!$S:$S,MATCH($B14,'Current List'!$A:$A,0))=0,"",INDEX('Current List'!$S:$S,MATCH($B14,'Current List'!$A:$A,0))) | L14: =IFERROR(IF(ISNUMBER(K14),K14,VALUE(LEFT(K14,1))),Assumptions!$B$4) | M14: =IF(K14="","TBD","Confirmed") | N14: =INDEX('Current List'!$T:$T,MATCH($B14,'Current List'!$A:$A,0)) | O14: =WORKDAY(N14,-Assumptions!$B$5) | P14: =WORKDAY(O14,-VLOOKUP(A14,Assumptions!$A$11:$B$16,2,FALSE)) | Q14: =P14-WEEKDAY(P14,3) | R14: =INDEX('Current List'!$U:$U,MATCH($B14,'Current List'!$A:$A,0)) | S14: =TRIM(IF(J14<>"Approved","Layout not validated; ","")&IF(M14="TBD","Config TBD (default units); ","")&IF(H14="TBD","Labor TBD; ","")&IF(A14="Outlier","Remote / out of route; ","")&IF(A14="South TX","Long haul; ",""))
A15: DFW | B15: 189426 | C15: 5799 | D15: Mckinney | E15: TX | F15: 75070 | G15: =INDEX('Current List'!$L:$L,MATCH($B15,'Current List'!$A:$A,0)) | H15: =IF(INDEX('Current List'!$O:$O,MATCH($B15,'Current List'!$A:$A,0))=0,"TBD",INDEX('Current List'!$O:$O,MATCH($B15,'Current List'!$A:$A,0))) | I15: =IF(OR(INDEX('Current List'!$R:$R,MATCH($B15,'Current List'!$A:$A,0))=0,INDEX('Current List'!$R:$R,MATCH($B15,'Current List'!$A:$A,0))="N/A"),"-",INDEX('Current List'!$R:$R,MATCH($B15,'Current List'!$A:$A,0))) | J15: =INDEX('Current List'!$N:$N,MATCH($B15,'Current List'!$A:$A,0)) | K15: =IF(INDEX('Current List'!$S:$S,MATCH($B15,'Current List'!$A:$A,0))=0,"",INDEX('Current List'!$S:$S,MATCH($B15,'Current List'!$A:$A,0))) | L15: =IFERROR(IF(ISNUMBER(K15),K15,VALUE(LEFT(K15,1))),Assumptions!$B$4) | M15: =IF(K15="","TBD","Confirmed") | N15: =INDEX('Current List'!$T:$T,MATCH($B15,'Current List'!$A:$A,0)) | O15: =WORKDAY(N15,-Assumptions!$B$5) | P15: =WORKDAY(O15,-VLOOKUP(A15,Assumptions!$A$11:$B$16,2,FALSE)) | Q15: =P15-WEEKDAY(P15,3) | R15: =INDEX('Current List'!$U:$U,MATCH($B15,'Current List'!$A:$A,0)) | S15: =TRIM(IF(J15<>"Approved","Layout not validated; ","")&IF(M15="TBD","Config TBD (default units); ","")&IF(H15="TBD","Labor TBD; ","")&IF(A15="Outlier","Remote / out of route; ","")&IF(A15="South TX","Long haul; ",""))
A16: DFW | B16: 190031 | C16: 10635 | D16: Royse City | E16: TX | F16: 75189 | G16: =INDEX('Current List'!$L:$L,MATCH($B16,'Current List'!$A:$A,0)) | H16: =IF(INDEX('Current List'!$O:$O,MATCH($B16,'Current List'!$A:$A,0))=0,"TBD",INDEX('Current List'!$O:$O,MATCH($B16,'Current List'!$A:$A,0))) | I16: =IF(OR(INDEX('Current List'!$R:$R,MATCH($B16,'Current List'!$A:$A,0))=0,INDEX('Current List'!$R:$R,MATCH($B16,'Current List'!$A:$A,0))="N/A"),"-",INDEX('Current List'!$R:$R,MATCH($B16,'Current List'!$A:$A,0))) | J16: =INDEX('Current List'!$N:$N,MATCH($B16,'Current List'!$A:$A,0)) | K16: =IF(INDEX('Current List'!$S:$S,MATCH($B16,'Current List'!$A:$A,0))=0,"",INDEX('Current List'!$S:$S,MATCH($B16,'Current List'!$A:$A,0))) | L16: =IFERROR(IF(ISNUMBER(K16),K16,VALUE(LEFT(K16,1))),Assumptions!$B$4) | M16: =IF(K16="","TBD","Confirmed") | N16: =INDEX('Current List'!$T:$T,MATCH($B16,'Current List'!$A:$A,0)) | O16: =WORKDAY(N16,-Assumptions!$B$5) | P16: =WORKDAY(O16,-VLOOKUP(A16,Assumptions!$A$11:$B$16,2,FALSE)) | Q16: =P16-WEEKDAY(P16,3) | R16: =INDEX('Current List'!$U:$U,MATCH($B16,'Current List'!$A:$A,0)) | S16: =TRIM(IF(J16<>"Approved","Layout not validated; ","")&IF(M16="TBD","Config TBD (default units); ","")&IF(H16="TBD","Labor TBD; ","")&IF(A16="Outlier","Remote / out of route; ","")&IF(A16="South TX","Long haul; ",""))
... A69: Outlier | B69: 189116 | C69: 1543 | D69: Amarillo | E69: TX | F69: 79119 | G69: =INDEX('Current List'!$L:$L,MATCH($B69,'Current List'!$A:$A,0)) | H69: =IF(INDEX('Current List'!$O:$O,MATCH($B69,'Current List'!$A:$A,0))=0,"TBD",INDEX('Current List'!$O:$O,MATCH($B69,'Current List'!$A:$A,0))) | I69: =IF(OR(INDEX('Current List'!$R:$R,MATCH($B69,'Current List'!$A:$A,0))=0,INDEX('Current List'!$R:$R,MATCH($B69,'Current List'!$A:$A,0))="N/A"),"-",INDEX('Current List'!$R:$R,MATCH($B69,'Current List'!$A:$A,0))) | J69: =INDEX('Current List'!$N:$N,MATCH($B69,'Current List'!$A:$A,0)) | K69: =IF(INDEX('Current List'!$S:$S,MATCH($B69,'Current List'!$A:$A,0))=0,"",INDEX('Current List'!$S:$S,MATCH($B69,'Current List'!$A:$A,0))) | L69: =IFERROR(IF(ISNUMBER(K69),K69,VALUE(LEFT(K69,1))),Assumptions!$B$4) | M69: =IF(K69="","TBD","Confirmed") | N69: =INDEX('Current List'!$T:$T,MATCH($B69,'Current List'!$A:$A,0)) | O69: =WORKDAY(N69,-Assumptions!$B$5) | P69: =WORKDAY(O69,-VLOOKUP(A69,Assumptions!$A$11:$B$16,2,FALSE)) | Q69: =P69-WEEKDAY(P69,3) | R69: =INDEX('Current List'!$U:$U,MATCH($B69,'Current List'!$A:$A,0)) | S69: =TRIM(IF(J69<>"Approved","Layout not validated; ","")&IF(M69="TBD","Config TBD (default units); ","")&IF(H69="TBD","Labor TBD; ","")&IF(A69="Outlier","Remote / out of route; ","")&IF(A69="South TX","Long haul; ",""))
A70: Total | C70: =COUNTA(C5:C69) | L70: =SUM(L5:L69)

Sheet Region Summary
A1: Region x MSD week: stores and units
A3: Stores
A4: Region | B4: 46300 | C4: 46307 | D4: 46314 | E4: 46321 | F4: 46328 | G4: 46335 | H4: 46342 | I4: 46356 | J4: Total
A5: DFW | B5: =COUNTIFS('Logistics Plan'!$A$5:$A$69,$A5,'Logistics Plan'!$N$5:$N$69,B$4) | C5: =COUNTIFS('Logistics Plan'!$A$5:$A$69,$A5,'Logistics Plan'!$N$5:$N$69,C$4) | D5: =COUNTIFS('Logistics Plan'!$A$5:$A$69,$A5,'Logistics Plan'!$N$5:$N$69,D$4) | E5: =COUNTIFS('Logistics Plan'!$A$5:$A$69,$A5,'Logistics Plan'!$N$5:$N$69,E$4) | F5: =COUNTIFS('Logistics Plan'!$A$5:$A$69,$A5,'Logistics Plan'!$N$5:$N$69,F$4) | G5: =COUNTIFS('Logistics Plan'!$A$5:$A$69,$A5,'Logistics Plan'!$N$5:$N$69,G$4) | H5: =COUNTIFS('Logistics Plan'!$A$5:$A$69,$A5,'Logistics Plan'!$N$5:$N$69,H$4) | I5: =COUNTIFS('Logistics Plan'!$A$5:$A$69,$A5,'Logistics Plan'!$N$5:$N$69,I$4) | J5: =SUM(B5:I5)
A6: Houston | B6: =COUNTIFS('Logistics Plan'!$A$5:$A$69,$A6,'Logistics Plan'!$N$5:$N$69,B$4) | C6: =COUNTIFS('Logistics Plan'!$A$5:$A$69,$A6,'Logistics Plan'!$N$5:$N$69,C$4) | D6: =COUNTIFS('Logistics Plan'!$A$5:$A$69,$A6,'Logistics Plan'!$N$5:$N$69,D$4) | E6: =COUNTIFS('Logistics Plan'!$A$5:$A$69,$A6,'Logistics Plan'!$N$5:$N$69,E$4) | F6: =COUNTIFS('Logistics Plan'!$A$5:$A$69,$A6,'Logistics Plan'!$N$5:$N$69,F$4) | G6: =COUNTIFS('Logistics Plan'!$A$5:$A$69,$A6,'Logistics Plan'!$N$5:$N$69,G$4) | H6: =COUNTIFS('Logistics Plan'!$A$5:$A$69,$A6,'Logistics Plan'!$N$5:$N$69,H$4) | I6: =COUNTIFS('Logistics Plan'!$A$5:$A$69,$A6,'Logistics Plan'!$N$5:$N$69,I$4) | J6: =SUM(B6:I6)
A7: Austin / Central | B7: =COUNTIFS('Logistics Plan'!$A$5:$A$69,$A7,'Logistics Plan'!$N$5:$N$69,B$4) | C7: =COUNTIFS('Logistics Plan'!$A$5:$A$69,$A7,'Logistics Plan'!$N$5:$N$69,C$4) | D7: =COUNTIFS('Logistics Plan'!$A$5:$A$69,$A7,'Logistics Plan'!$N$5:$N$69,D$4) | E7: =COUNTIFS('Logistics Plan'!$A$5:$A$69,$A7,'Logistics Plan'!$N$5:$N$69,E$4) | F7: =COUNTIFS('Logistics Plan'!$A$5:$A$69,$A7,'Logistics Plan'!$N$5:$N$69,F$4) | G7: =COUNTIFS('Logistics Plan'!$A$5:$A$69,$A7,'Logistics Plan'!$N$5:$N$69,G$4) | H7: =COUNTIFS('Logistics Plan'!$A$5:$A$69,$A7,'Logistics Plan'!$N$5:$N$69,H$4) | I7: =COUNTIFS('Logistics Plan'!$A$5:$A$69,$A7,'Logistics Plan'!$N$5:$N$69,I$4) | J7: =SUM(B7:I7)
A8: San Antonio | B8: =COUNTIFS('Logistics Plan'!$A$5:$A$69,$A8,'Logistics Plan'!$N$5:$N$69,B$4) | C8: =COUNTIFS('Logistics Plan'!$A$5:$A$69,$A8,'Logistics Plan'!$N$5:$N$69,C$4) | D8: =COUNTIFS('Logistics Plan'!$A$5:$A$69,$A8,'Logistics Plan'!$N$5:$N$69,D$4) | E8: =COUNTIFS('Logistics Plan'!$A$5:$A$69,$A8,'Logistics Plan'!$N$5:$N$69,E$4) | F8: =COUNTIFS('Logistics Plan'!$A$5:$A$69,$A8,'Logistics Plan'!$N$5:$N$69,F$4) | G8: =COUNTIFS('Logistics Plan'!$A$5:$A$69,$A8,'Logistics Plan'!$N$5:$N$69,G$4) | H8: =COUNTIFS('Logistics Plan'!$A$5:$A$69,$A8,'Logistics Plan'!$N$5:$N$69,H$4) | I8: =COUNTIFS('Logistics Plan'!$A$5:$A$69,$A8,'Logistics Plan'!$N$5:$N$69,I$4) | J8: =SUM(B8:I8)
A9: South TX | B9: =COUNTIFS('Logistics Plan'!$A$5:$A$69,$A9,'Logistics Plan'!$N$5:$N$69,B$4) | C9: =COUNTIFS('Logistics Plan'!$A$5:$A$69,$A9,'Logistics Plan'!$N$5:$N$69,C$4) | D9: =COUNTIFS('Logistics Plan'!$A$5:$A$69,$A9,'Logistics Plan'!$N$5:$N$69,D$4) | E9: =COUNTIFS('Logistics Plan'!$A$5:$A$69,$A9,'Logistics Plan'!$N$5:$N$69,E$4) | F9: =COUNTIFS('Logistics Plan'!$A$5:$A$69,$A9,'Logistics Plan'!$N$5:$N$69,F$4) | G9: =COUNTIFS('Logistics Plan'!$A$5:$A$69,$A9,'Logistics Plan'!$N$5:$N$69,G$4) | H9: =COUNTIFS('Logistics Plan'!$A$5:$A$69,$A9,'Logistics Plan'!$N$5:$N$69,H$4) | I9: =COUNTIFS('Logistics Plan'!$A$5:$A$69,$A9,'Logistics Plan'!$N$5:$N$69,I$4) | J9: =SUM(B9:I9)
A10: Outlier | B10: =COUNTIFS('Logistics Plan'!$A$5:$A$69,$A10,'Logistics Plan'!$N$5:$N$69,B$4) | C10: =COUNTIFS('Logistics Plan'!$A$5:$A$69,$A10,'Logistics Plan'!$N$5:$N$69,C$4) | D10: =COUNTIFS('Logistics Plan'!$A$5:$A$69,$A10,'Logistics Plan'!$N$5:$N$69,D$4) | E10: =COUNTIFS('Logistics Plan'!$A$5:$A$69,$A10,'Logistics Plan'!$N$5:$N$69,E$4) | F10: =COUNTIFS('Logistics Plan'!$A$5:$A$69,$A10,'Logistics Plan'!$N$5:$N$69,F$4) | G10: =COUNTIFS('Logistics Plan'!$A$5:$A$69,$A10,'Logistics Plan'!$N$5:$N$69,G$4) | H10: =COUNTIFS('Logistics Plan'!$A$5:$A$69,$A10,'Logistics Plan'!$N$5:$N$69,H$4) | I10: =COUNTIFS('Logistics Plan'!$A$5:$A$69,$A10,'Logistics Plan'!$N$5:$N$69,I$4) | J10: =SUM(B10:I10)
A11: Total | B11: =SUM(B5:B10) | C11: =SUM(C5:C10) | D11: =SUM(D5:D10) | E11: =SUM(E5:E10) | F11: =SUM(F5:F10) | G11: =SUM(G5:G10) | H11: =SUM(H5:H10) | I11: =SUM(I5:I10) | J11: =SUM(J5:J10)
A13: Units (default used where config TBD)
A14: Region | B14: 46300 | C14: 46307 | D14: 46314 | E14: 46321 | F14: 46328 | G14: 46335 | H14: 46342 | I14: 46356 | J14: Total
A15: DFW | B15: =SUMIFS('Logistics Plan'!$L$5:$L$69,'Logistics Plan'!$A$5:$A$69,$A15,'Logistics Plan'!$N$5:$N$69,B$14) | C15: =SUMIFS('Logistics Plan'!$L$5:$L$69,'Logistics Plan'!$A$5:$A$69,$A15,'Logistics Plan'!$N$5:$N$69,C$14) | D15: =SUMIFS('Logistics Plan'!$L$5:$L$69,'Logistics Plan'!$A$5:$A$69,$A15,'Logistics Plan'!$N$5:$N$69,D$14) | E15: =SUMIFS('Logistics Plan'!$L$5:$L$69,'Logistics Plan'!$A$5:$A$69,$A15,'Logistics Plan'!$N$5:$N$69,E$14) | F15: =SUMIFS('Logistics Plan'!$L$5:$L$69,'Logistics Plan'!$A$5:$A$69,$A15,'Logistics Plan'!$N$5:$N$69,F$14) | G15: =SUMIFS('Logistics Plan'!$L$5:$L$69,'Logistics Plan'!$A$5:$A$69,$A15,'Logistics Plan'!$N$5:$N$69,G$14) | H15: =SUMIFS('Logistics Plan'!$L$5:$L$69,'Logistics Plan'!$A$5:$A$69,$A15,'Logistics Plan'!$N$5:$N$69,H$14) | I15: =SUMIFS('Logistics Plan'!$L$5:$L$69,'Logistics Plan'!$A$5:$A$69,$A15,'Logistics Plan'!$N$5:$N$69,I$14) | J15: =SUM(B15:I15)
A16: Houston | B16: =SUMIFS('Logistics Plan'!$L$5:$L$69,'Logistics Plan'!$A$5:$A$69,$A16,'Logistics Plan'!$N$5:$N$69,B$14) | C16: =SUMIFS('Logistics Plan'!$L$5:$L$69,'Logistics Plan'!$A$5:$A$69,$A16,'Logistics Plan'!$N$5:$N$69,C$14) | D16: =SUMIFS('Logistics Plan'!$L$5:$L$69,'Logistics Plan'!$A$5:$A$69,$A16,'Logistics Plan'!$N$5:$N$69,D$14) | E16: =SUMIFS('Logistics Plan'!$L$5:$L$69,'Logistics Plan'!$A$5:$A$69,$A16,'Logistics Plan'!$N$5:$N$69,E$14) | F16: =SUMIFS('Logistics Plan'!$L$5:$L$69,'Logistics Plan'!$A$5:$A$69,$A16,'Logistics Plan'!$N$5:$N$69,F$14) | G16: =SUMIFS('Logistics Plan'!$L$5:$L$69,'Logistics Plan'!$A$5:$A$69,$A16,'Logistics Plan'!$N$5:$N$69,G$14) | H16: =SUMIFS('Logistics Plan'!$L$5:$L$69,'Logistics Plan'!$A$5:$A$69,$A16,'Logistics Plan'!$N$5:$N$69,H$14) | I16: =SUMIFS('Logistics Plan'!$L$5:$L$69,'Logistics Plan'!$A$5:$A$69,$A16,'Logistics Plan'!$N$5:$N$69,I$14) | J16: =SUM(B16:I16)
A17: Austin / Central | B17: =SUMIFS('Logistics Plan'!$L$5:$L$69,'Logistics Plan'!$A$5:$A$69,$A17,'Logistics Plan'!$N$5:$N$69,B$14) | C17: =SUMIFS('Logistics Plan'!$L$5:$L$69,'Logistics Plan'!$A$5:$A$69,$A17,'Logistics Plan'!$N$5:$N$69,C$14) | D17: =SUMIFS('Logistics Plan'!$L$5:$L$69,'Logistics Plan'!$A$5:$A$69,$A17,'Logistics Plan'!$N$5:$N$69,D$14) | E17: =SUMIFS('Logistics Plan'!$L$5:$L$69,'Logistics Plan'!$A$5:$A$69,$A17,'Logistics Plan'!$N$5:$N$69,E$14) | F17: =SUMIFS('Logistics Plan'!$L$5:$L$69,'Logistics Plan'!$A$5:$A$69,$A17,'Logistics Plan'!$N$5:$N$69,F$14) | G17: =SUMIFS('Logistics Plan'!$L$5:$L$69,'Logistics Plan'!$A$5:$A$69,$A17,'Logistics Plan'!$N$5:$N$69,G$14) | H17: =SUMIFS('Logistics Plan'!$L$5:$L$69,'Logistics Plan'!$A$5:$A$69,$A17,'Logistics Plan'!$N$5:$N$69,H$14) | I17: =SUMIFS('Logistics Plan'!$L$5:$L$69,'Logistics Plan'!$A$5:$A$69,$A17,'Logistics Plan'!$N$5:$N$69,I$14) | J17: =SUM(B17:I17)
A18: San Antonio | B18: =SUMIFS('Logistics Plan'!$L$5:$L$69,'Logistics Plan'!$A$5:$A$69,$A18,'Logistics Plan'!$N$5:$N$69,B$14) | C18: =SUMIFS('Logistics Plan'!$L$5:$L$69,'Logistics Plan'!$A$5:$A$69,$A18,'Logistics Plan'!$N$5:$N$69,C$14) | D18: =SUMIFS('Logistics Plan'!$L$5:$L$69,'Logistics Plan'!$A$5:$A$69,$A18,'Logistics Plan'!$N$5:$N$69,D$14) | E18: =SUMIFS('Logistics Plan'!$L$5:$L$69,'Logistics Plan'!$A$5:$A$69,$A18,'Logistics Plan'!$N$5:$N$69,E$14) | F18: =SUMIFS('Logistics Plan'!$L$5:$L$69,'Logistics Plan'!$A$5:$A$69,$A18,'Logistics Plan'!$N$5:$N$69,F$14) | G18: =SUMIFS('Logistics Plan'!$L$5:$L$69,'Logistics Plan'!$A$5:$A$69,$A18,'Logistics Plan'!$N$5:$N$69,G$14) | H18: =SUMIFS('Logistics Plan'!$L$5:$L$69,'Logistics Plan'!$A$5:$A$69,$A18,'Logistics Plan'!$N$5:$N$69,H$14) | I18: =SUMIFS('Logistics Plan'!$L$5:$L$69,'Logistics Plan'!$A$5:$A$69,$A18,'Logistics Plan'!$N$5:$N$69,I$14) | J18: =SUM(B18:I18)
A19: South TX | B19: =SUMIFS('Logistics Plan'!$L$5:$L$69,'Logistics Plan'!$A$5:$A$69,$A19,'Logistics Plan'!$N$5:$N$69,B$14) | C19: =SUMIFS('Logistics Plan'!$L$5:$L$69,'Logistics Plan'!$A$5:$A$69,$A19,'Logistics Plan'!$N$5:$N$69,C$14) | D19: =SUMIFS('Logistics Plan'!$L$5:$L$69,'Logistics Plan'!$A$5:$A$69,$A19,'Logistics Plan'!$N$5:$N$69,D$14) | E19: =SUMIFS('Logistics Plan'!$L$5:$L$69,'Logistics Plan'!$A$5:$A$69,$A19,'Logistics Plan'!$N$5:$N$69,E$14) | F19: =SUMIFS('Logistics Plan'!$L$5:$L$69,'Logistics Plan'!$A$5:$A$69,$A19,'Logistics Plan'!$N$5:$N$69,F$14) | G19: =SUMIFS('Logistics Plan'!$L$5:$L$69,'Logistics Plan'!$A$5:$A$69,$A19,'Logistics Plan'!$N$5:$N$69,G$14) | H19: =SUMIFS('Logistics Plan'!$L$5:$L$69,'Logistics Plan'!$A$5:$A$69,$A19,'Logistics Plan'!$N$5:$N$69,H$14) | I19: =SUMIFS('Logistics Plan'!$L$5:$L$69,'Logistics Plan'!$A$5:$A$69,$A19,'Logistics Plan'!$N$5:$N$69,I$14) | J19: =SUM(B19:I19)
A20: Outlier | B20: =SUMIFS('Logistics Plan'!$L$5:$L$69,'Logistics Plan'!$A$5:$A$69,$A20,'Logistics Plan'!$N$5:$N$69,B$14) | C20: =SUMIFS('Logistics Plan'!$L$5:$L$69,'Logistics Plan'!$A$5:$A$69,$A20,'Logistics Plan'!$N$5:$N$69,C$14) | D20: =SUMIFS('Logistics Plan'!$L$5:$L$69,'Logistics Plan'!$A$5:$A$69,$A20,'Logistics Plan'!$N$5:$N$69,D$14) | E20: =SUMIFS('Logistics Plan'!$L$5:$L$69,'Logistics Plan'!$A$5:$A$69,$A20,'Logistics Plan'!$N$5:$N$69,E$14) | F20: =SUMIFS('Logistics Plan'!$L$5:$L$69,'Logistics Plan'!$A$5:$A$69,$A20,'Logistics Plan'!$N$5:$N$69,F$14) | G20: =SUMIFS('Logistics Plan'!$L$5:$L$69,'Logistics Plan'!$A$5:$A$69,$A20,'Logistics Plan'!$N$5:$N$69,G$14) | H20: =SUMIFS('Logistics Plan'!$L$5:$L$69,'Logistics Plan'!$A$5:$A$69,$A20,'Logistics Plan'!$N$5:$N$69,H$14) | I20: =SUMIFS('Logistics Plan'!$L$5:$L$69,'Logistics Plan'!$A$5:$A$69,$A20,'Logistics Plan'!$N$5:$N$69,I$14) | J20: =SUM(B20:I20)
A21: Total | B21: =SUM(B15:B20) | C21: =SUM(C15:C20) | D21: =SUM(D15:D20) | E21: =SUM(E15:E20) | F21: =SUM(F15:F20) | G21: =SUM(G15:G20) | H21: =SUM(H15:H20) | I21: =SUM(I15:I20) | J21: =SUM(J15:J20)
A23: Crew-days needed (stores x install days per store)
A24: Peak week crew-days | B24: =MAX(B11:I11)*Assumptions!$B$6
A25: Total crew-days | B25: =J11*Assumptions!$B$6
A26: Crews needed at peak if each does 5 install days/week | B26: =ROUNDUP(B24/5,0)

Sheet Map Data
A1: Region | B1: Store # | C1: CS# | D1: Address | E1: City | F1: State | G1: Zip | H1: Latitude | I1: Longitude | J1: MSD | K1: Location basis
A2: DFW | B2: 10880 | C2: 190032 | D2: 8580 N. Macarthur Blvd | E2: Irving | F2: TX | G2: 75063 | H2: 32.92358 | I2: -96.95528 | J2: 46300 | K2: Census address match
A3: DFW | B3: 10642 | C3: 190033 | D3: 1101 Fm 2181 | E3: Corinth | F3: TX | G3: 76210 | H3: 33.13282 | I3: -97.09509 | J3: 46307 | K3: OSM CVS store match (FM 2181 = Teasley Ln)
A4: DFW | B4: 10324 | C4: 189985 | D4: 6420 Gaston Ave. | E4: Dallas | F4: TX | G4: 75214 | H4: 32.8148 | I4: -96.75177 | J4: 46307 | K4: Census address match
A5: DFW | B5: 8345 | C5: 189620 | D5: 5195 Lake Ridge Pkwy. | E5: Grand Prairie | F5: TX | G5: 75052 | H5: 32.64808 | I5: -97.04393 | J5: 46314 | K5: Census address match
A6: DFW | B6: 6865 | C6: 189473 | D6: 1099 W. Main St | E6: Lewisville | F6: TX | G6: 75067 | H6: 33.04221 | I6: -97.02046 | J6: 46314 | K6: Census address match
A7: DFW | B7: 3187 | C7: 189281 | D7: 1000 E. Sandy Lake Rd. | E7: Coppell | F7: TX | G7: 75019 | H7: 32.96947 | I7: -96.95857 | J7: 46321 | K7: Census address match
A8: DFW | B8: 7787 | C8: 189528 | D8: 2220 Cross Timbers Rd | E8: Flower Mound | F8: TX | G8: 75028 | H8: 33.03457 | I8: -97.06252 | J8: 46321 | K8: Census address match
A9: DFW | B9: 6960 | C9: 189474 | D9: 2142 N Josey Ln | E9: Carrollton | F9: TX | G9: 75006 | H9: 32.97154 | I9: -96.8898 | J9: 46328 | K9: Census address match
A10: DFW | B10: 7804 | C10: 189529 | D10: 6401 W Parker Rd | E10: Plano | F10: TX | G10: 75093 | H10: 33.04537 | I10: -96.8396 | J10: 46328 | K10: Census address match
A11: DFW | B11: 10271 | C11: 189986 | D11: 1510 W. Hickory St. | E11: Denton | F11: TX | G11: 76201 | H11: 33.21472 | I11: -97.14858 | J11: 46335 | K11: Census address match
A12: DFW | B12: 5799 | C12: 189426 | D12: 6301 El Dorado Pkwy. | E12: Mckinney | F12: TX | G12: 75070 | H12: 33.17397 | I12: -96.69909 | J12: 46335 | K12: Census address match
A13: DFW | B13: 10635 | C13: 190031 | D13: 476 W. 1-30 | E13: Royse City | F13: TX | G13: 75189 | H13: 32.96545 | I13: -96.34001 | J13: 46335 | K13: OSM CVS store match
... A66: Outlier | B66: 1543 | C66: 189116 | D66: 7301 Hillside Rd. | E66: Amarillo | F66: TX | G66: 79119 | H66: 35.14673 | I66: -101.92013 | J66: 46356 | K66: Census address match

Sheet Open Items
A1: Open items to close before the plan is final
A3: Item | B3: Detail | C3: Owner
A4: Ship-from point / vendor lead time | B4: Transit days on Assumptions are placeholders. Need the vendor ship point and production lead time. | C4: Owner: Procurement / vendor
A5: Meaning and firmness of MSD | B5: Plan treats MSD as the install window opening and CSD (MSD + 7) as the deadline. Confirm with CVS/program manager. | C5: Owner: PM
A6: Unit configs for stores not validated | B6: 30 stores show Not Validated Yet and have no unit config. Plan uses the default and flags them; PO quantities should not be locked until configs are confirmed. | C6: Owner: CVS / layout validation
A7: Labor model TBD | B7: MV vs Store Labor is blank for the not-validated stores and some validated stores (hours 0). Affects who receives/installs. | C7: Owner: PM
A8: Remote stores | B8: Amarillo (1543) and New Orleans (10594) are far from any cluster; decide on dedicated delivery or bundling with another run. | C8: Owner: Logistics
A9: Receiving windows / store contacts | B9: Need site delivery hours, dock/no-dock, and receiving contacts per store, particularly for freestanding pads and convenience store types. | C9: Owner: Field ops
A10: Crew plan | B10: Region Summary gives peak-week load; confirm self-perform vs sub and travel/lodging for South TX and outliers. | C10: Owner: COO / Ops
A11: Tie to PO | B11: Once configs firm up, roll units per region into the vendor PO and delivery schedule. | C11: Owner: Procurement
